Workbook

Sheet Definitions
B2: Price modelling
B4: Value driver overview
B5: Value driver name | C5: Definition
B6: Brand Awareness | C6: The degree to which customers value a platform’s market reputation and recognition to enhance the credibility and adoption of their credentials
B7: Analytics | C7: The importance customers place on access to actionable data and insights to demonstrate program impact (ROI) and inform decision-making
B8: Ease of Use (Issuer) | C8: The extent to which customers prioritize an intuitive and efficient administrative experience to minimize effort and operational complexity
B9: Customer Support | C9: How reliable and effective buyers perceive the support experience to be in resolving issues and enabling success
B10: Customization | C10: The degree to which buyers feel the platform can be adapted to their specific branding, workflows, and requirements
B11: Ease of Use (Earner) | C11: How simple and intuitive buyers believe the experience is for end users, especially in driving engagement, completion, and sharing
B12: Security | C12: How confident buyers are in the platform’s ability to protect data, ensure compliance, and maintain credential integrity
B15: Market strategies
B16: Name | C16: Definition
B17: Challenger/gain market share | C17: Some markets have currently unrealized potential, due to a currently worse value proposition than the competition or an overall growth in the market. In these markets, pricing lower than the competition/lower than the provided value can help in growing the market share and maximize profitability in the long term.
B18: On par/no special objective | C18: Default option. In competitive markets, products should be priced according to the value they provide and value differences between competitors should be reflected in the prices of products.
B19: Market leader/defend market share | C19: In markets, in which PTE is already in a dominant position but competitors are trying to buy market share, one possible strategy is to price (slightly) lower than the provided value in order to prevent competitors from gaining market share.
B20: Margin skimming | C20: Markets can become less attractive if they are showing signs of a decline of the overall customer base or increasing difficulties of conducting business. In these markets, a premium can be charged in order to maximize profitability from a declining number of customers.
B22: Calculation modifiers
B23: Name | C23: Definition
B24: Market strategies | C24: See definitions above. For each of the strategic market objectives, a positive or negative percentage in-/decrease in price calculation can be added. These determine how aggressively these objectives are followed and need to be defined globally, per region, or per country.
B25: Max contribution per value driver | C25: This modifier defines how high the maximum price in-/decrease can be for a single value driver that has the highest importance and a strong negative or positive performance. The contribution of all other value drivers is derived from this value.
B26: Max total price range | C26: This is calculated directly from the "Max contribution per value driver" and shows how big the maximum achievable price de/-increase would be if all value drivers had the strongest negative/positive performance rating.

Sheet Step 1 VD Relevance
B2: Step 1: Value Driver Relevance
B4: Please specify the market for this exercise: | D4: USA
B5: Please specify the persona for this exercise: | D5: SMB
B7: Please rank these value drivers based on their relevance to the test taker
B8: 1 = most important; 7 = least important
B10: Value driver | C10: Rank Final | D10: Rank EP | E10: Rank NG | F10: Rank CW | G10: Rank KL | H10: Rank BG | I10: Workshop avg. rank
B11: Brand Awareness | C11: =RANK(I11,$I$11:$I$17,1) | E11: 1 | F11: 4 | G11: 4 | I11: =AVERAGE(D11:H11)
B12: Analytics | C12: =RANK(I12,$I$11:$I$17,1) | E12: 6 | F12: 3 | G12: 5 | I12: =AVERAGE(D12:H12)
B13: Ease of Use (Issuer) | C13: =RANK(I13,$I$11:$I$17,1) | E13: 2 | F13: 2 | G13: 1 | I13: =AVERAGE(D13:H13)
B14: Customer Support | C14: =RANK(I14,$I$11:$I$17,1) | E14: 3 | F14: 1 | G14: 2 | I14: =AVERAGE(D14:H14)
B15: Customization | C15: =RANK(I15,$I$11:$I$17,1) | E15: 4 | F15: 5 | G15: 6 | I15: =AVERAGE(D15:H15)
B16: Ease of Use (Earner) | C16: =RANK(I16,$I$11:$I$17,1) | E16: 5 | F16: 6 | G16: 3 | I16: =AVERAGE(D16:H16)
B17: Security | C17: =RANK(I17,$I$11:$I$17,1) | E17: 7 | F17: 7 | G17: 7 | I17: =AVERAGE(D17:H17)
B20: Please make sure to rank all 7 Value Drivers
B21: You are good to go. Please proceed to Step 2.

Sheet Step 2 competition
B2: Step 2: Market Situation
B4: Which are the most relevant competitors in the market? | D4: =AND( COUNTA($C$18:$C$20)=3, COUNTA($C$29:$C$31)=3, OR($B$10="(enter name here)", AND($C$21<>"",$C$32<>"")), OR($B$11="(enter name here)", AND($C$22<>"",$C$33<>"")), OR($B$12="(enter name here)", AND($C$23<>"",$C$34<>"")) )
B6: Competitor name
B7: Credly
B8: Accredible
B9: Sertifier
B10: Instructure/Canvas
B11: BadgeCert
B12: (enter name here)
B15: Fill in the prices (in USD) of the competitors you added
B17: Competitor name | C17: Price
B18: =IF(B7="(enter name here)","",B7)
B19: =IF(B8="(enter name here)","",B8)
B20: =IF(B9="(enter name here)","",B9)
B21: =IF(B10="(enter name here)","",B10)
B22: =IF(B11="(enter name here)","",B11)
B23: =IF(B12="(enter name here)","",B12)
B26: Please give an estimate of the relative market share of each competitor
B28: Competitor name | C28: Market share
B29: =IF(B7="(enter name here)","",B7)
B30: =IF(B8="(enter name here)","",B8)
B31: =IF(B9="(enter name here)","",B9)
B32: =IF(B10="(enter name here)","",B10)
B33: =IF(B11="(enter name here)","",B11)
B34: =IF(B12="(enter name here)","",B12)
B36: Please fill in a price and market share for all relevant competitors
B37: You are good to go. Please proceed to Step 3.

Sheet Step 3 Value assessment
B2: Step 3: Competition Value Assessment
B4: Please evaluate each competitor's performance on each of the value drivers from -2 to +2 | H4: =AND( COUNTA($D$9:$F$15)=ROWS($D$9:$F$15)*COLUMNS($D$9:$F$15), OR($G$8="",COUNTA($G$9:$G$15)=ROWS($G$9:$G$15)), OR($H$8="",COUNTA($H$9:$H$15)=ROWS($H$9:$H$15)), OR($I$8="",COUNTA($I$9:$I$15)=ROWS($I$9:$I$15)) )
B5: 0 = market average; 2 = leading the market; -2 = significantly lacking
I7: EP | M7: NG | Q7: CW | U7: KL | Y7: BG
B8: Rank | C8: Value driver name | D8: =IF('Step 2 competition'!B7="(enter name here)","",'Step 2 competition'!B7) | E8: =IF('Step 2 competition'!B8="(enter name here)","",'Step 2 competition'!B8) | F8: =IF('Step 2 competition'!B9="(enter name here)","",'Step 2 competition'!B9) | G8: =IF('Step 2 competition'!B10="(enter name here)","",'Step 2 competition'!B10) | H8: =IF('Step 2 competition'!B11="(enter name here)","",'Step 2 competition'!B11) | I8: Credly | M8: Credly | N8: Accredible | O8: Sertifier | P8: Badgecert | Q8: Credly | R8: Accredible | U8: Credly | V8: Accredible | W8: Sertifier | X8: Instructure/Canvas | Y8: Credly
B9: 1 | C9: =_xlfn.XLOOKUP(B9,'Step 1 VD Relevance'!$C$11:$C$18,'Step 1 VD Relevance'!$B$11:$B$18,"",0) | D9: =AVERAGE(I9,M9,Q9,U9,Y9) | E9: =AVERAGE(J9,N9,R9,V9,Z9) | F9: =AVERAGE(K9,O9,S9,W9,AA9) | G9: =X9 | H9: =P9 | M9: 2 | N9: 0 | O9: 1 | P9: 1 | Q9: 2 | R9: -2 | U9: 1 | V9: 1 | W9: 2 | X9: -1
B10: 2 | C10: =_xlfn.XLOOKUP(B10,'Step 1 VD Relevance'!$C$11:$C$18,'Step 1 VD Relevance'!$B$11:$B$18,"",0) | D10: =AVERAGE(I10,M10,Q10,U10,Y10) | E10: =AVERAGE(J10,N10,R10,V10,Z10) | F10: =AVERAGE(K10,O10,S10,W10,AA10) | G10: =X10 | H10: =P10 | M10: 0 | N10: 0 | O10: 1 | P10: 1 | Q10: 2 | R10: -2 | U10: 1 | V10: 1 | W10: 1 | X10: 0
B11: 3 | C11: =_xlfn.XLOOKUP(B11,'Step 1 VD Relevance'!$C$11:$C$18,'Step 1 VD Relevance'!$B$11:$B$18,"",0) | D11: =AVERAGE(I11,M11,Q11,U11,Y11) | E11: =AVERAGE(J11,N11,R11,V11,Z11) | F11: =AVERAGE(K11,O11,S11,W11,AA11) | G11: =X11 | H11: =P11 | M11: 1 | N11: 0 | O11: -1 | P11: -1 | Q11: 0 | R11: 0 | U11: 2 | V11: 1 | W11: 0 | X11: 0
B12: 4 | C12: =_xlfn.XLOOKUP(B12,'Step 1 VD Relevance'!$C$11:$C$18,'Step 1 VD Relevance'!$B$11:$B$18,"",0) | D12: =AVERAGE(I12,M12,Q12,U12,Y12) | E12: =AVERAGE(J12,N12,R12,V12,Z12) | F12: =AVERAGE(K12,O12,S12,W12,AA12) | G12: =X12 | H12: =P12 | M12: 1 | N12: 1 | O12: 0 | P12: 0 | Q12: 2 | R12: -1 | U12: 2 | V12: 1 | W12: -1 | X12: 0
B13: 5 | C13: =_xlfn.XLOOKUP(B13,'Step 1 VD Relevance'!$C$11:$C$18,'Step 1 VD Relevance'!$B$11:$B$18,"",0) | D13: =AVERAGE(I13,M13,Q13,U13,Y13) | E13: =AVERAGE(J13,N13,R13,V13,Z13) | F13: =AVERAGE(K13,O13,S13,W13,AA13) | G13: =X13 | H13: =P13 | M13: -1 | N13: 1 | O13: 1 | P13: 1 | Q13: -2 | R13: 2 | U13: 1 | V13: 1 | W13: 0 | X13: -1
B14: 6 | C14: =_xlfn.XLOOKUP(B14,'Step 1 VD Relevance'!$C$11:$C$18,'Step 1 VD Relevance'!$B$11:$B$18,"",0) | D14: =AVERAGE(I14,M14,Q14,U14,Y14) | E14: =AVERAGE(J14,N14,R14,V14,Z14) | F14: =AVERAGE(K14,O14,S14,W14,AA14) | G14: =X14 | H14: =P14 | M14: 1 | N14: 0 | O14: -1 | P14: -1 | Q14: 2 | R14: -2 | U14: 1 | V14: 2 | W14: 0 | X14: -1
B15: 7 | C15: =_xlfn.XLOOKUP(B15,'Step 1 VD Relevance'!$C$11:$C$18,'Step 1 VD Relevance'!$B$11:$B$18,"",0) | D15: =AVERAGE(I15,M15,Q15,U15,Y15) | E15: =AVERAGE(J15,N15,R15,V15,Z15) | F15: =AVERAGE(K15,O15,S15,W15,AA15) | G15: =X15 | H15: =P15 | M15: 2 | N15: -2 | O15: -2 | P15: -2 | Q15: 0 | R15: 0 | U15: 2 | V15: 1 | W15: -1 | X15: 1
B18: Please assess the performance for all value drivers for all relevant competitors.

Sheet Step 4 Results
B2: Step 4: Results and Price Recommendation
B4: Market: | C4: ='Step 1 VD Relevance'!D4 | E4: Current market leader: | F4: =INDEX('Step 2 competition'!$B$29:$B$33, MATCH(MAX('Step 2 competition'!$C$29:$C$33), 'Step 2 competition'!$C$29:$C$33, 0))
B5: 2024 revenue (USD): | C5: =_xlfn.XLOOKUP(C4,'2024 Revenue'!$A$2:$A$175,'2024 Revenue'!$B$2:$B$175,"",0) | E5: Current Credly market share | F5: ='Step 2 competition'!C29
C9: ='Step 2 competition'!C14
C10: =Calculations!B51
C11: =Calculations!B54
C12: =Calculations!B56
C13: =Calculations!B58
B31: Competitor | C31: =IF(Calculations!D26<>"",Calculations!D26,"") | D31: =IF(Calculations!E26<>"",Calculations!E26,"") | E31: =IF(Calculations!F26<>"",Calculations!F26,"") | F31: =IF(Calculations!G26<>"",Calculations!G26,"") | G31: =IF(Calculations!H26<>"",Calculations!H26,"")
B32: Value Score | C32: =IF(C31<>"",_xlfn.XLOOKUP(C31,Calculations!$D$13:$I$13,Calculations!$D$23:$I$23,"",0),"") | D32: =IF(D31<>"",_xlfn.XLOOKUP(D31,Calculations!$D$13:$I$13,Calculations!$D$23:$I$23,"",0),"") | E32: =IF(E31<>"",_xlfn.XLOOKUP(E31,Calculations!$D$13:$I$13,Calculations!$D$23:$I$23,"",0),"") | F32: =IF(F31<>"",_xlfn.XLOOKUP(F31,Calculations!$D$13:$I$13,Calculations!$D$23:$I$23,"",0),"") | G32: =IF(G31<>"",_xlfn.XLOOKUP(G31,Calculations!$D$13:$I$13,Calculations!$D$23:$I$23,"",0),"")
B33: Price | C33: =IF(C31<>"",_xlfn.XLOOKUP('Step 4 Results'!C31,Calculations!$D$26:$I$26,Calculations!$D$27:$I$27,"",0),"") | D33: =IF(D31<>"",_xlfn.XLOOKUP('Step 4 Results'!D31,Calculations!$D$26:$I$26,Calculations!$D$27:$I$27,"",0),"") | E33: =IF(E31<>"",_xlfn.XLOOKUP('Step 4 Results'!E31,Calculations!$D$26:$I$26,Calculations!$D$27:$I$27,"",0),"") | F33: =IF(F31<>"",_xlfn.XLOOKUP('Step 4 Results'!F31,Calculations!$D$26:$I$26,Calculations!$D$27:$I$27,"",0),"") | G33: =IF(G31<>"",_xlfn.XLOOKUP('Step 4 Results'!G31,Calculations!$D$26:$I$26,Calculations!$D$27:$I$27,"",0),"")
B34: Price per Value | C34: =IF(C31<>"",_xlfn.XLOOKUP('Step 4 Results'!C31,Calculations!$C$31:$C$36,Calculations!$H$31:$H$36,"",0),"") | D34: =IF(D31<>"",_xlfn.XLOOKUP('Step 4 Results'!D31,Calculations!$C$31:$C$36,Calculations!$H$31:$H$36,"",0),"") | E34: =IF(E31<>"",_xlfn.XLOOKUP('Step 4 Results'!E31,Calculations!$C$31:$C$36,Calculations!$H$31:$H$36,"",0),"") | F34: =IF(F31<>"",_xlfn.XLOOKUP('Step 4 Results'!F31,Calculations!$C$31:$C$36,Calculations!$H$31:$H$36,"",0),"") | G34: =IF(G31<>"",_xlfn.XLOOKUP('Step 4 Results'!G31,Calculations!$C$31:$C$36,Calculations!$H$31:$H$36,"",0),"")
B37: Recommended Price range | E37: USD | F37: =Calculations!B54

Sheet Calculations
B1: Results
B2: ='Step 3 Value assessment'!B8 | C2: ='Step 3 Value assessment'!C8 | D2: ='Step 3 Value assessment'!D8 | E2: ='Step 3 Value assessment'!E8 | F2: ='Step 3 Value assessment'!F8 | G2: ='Step 3 Value assessment'!G8 | H2: ='Step 3 Value assessment'!H8
B3: ='Step 3 Value assessment'!B9 | C3: ='Step 3 Value assessment'!C9 | D3: ='Step 3 Value assessment'!D9 | E3: ='Step 3 Value assessment'!E9 | F3: ='Step 3 Value assessment'!F9 | G3: ='Step 3 Value assessment'!G9 | H3: ='Step 3 Value assessment'!H9
B4: ='Step 3 Value assessment'!B10 | C4: ='Step 3 Value assessment'!C10 | D4: ='Step 3 Value assessment'!D10 | E4: ='Step 3 Value assessment'!E10 | F4: ='Step 3 Value assessment'!F10 | G4: ='Step 3 Value assessment'!G10 | H4: ='Step 3 Value assessment'!H10
B5: ='Step 3 Value assessment'!B11 | C5: ='Step 3 Value assessment'!C11 | D5: ='Step 3 Value assessment'!D11 | E5: ='Step 3 Value assessment'!E11 | F5: ='Step 3 Value assessment'!F11 | G5: ='Step 3 Value assessment'!G11 | H5: ='Step 3 Value assessment'!H11
B6: ='Step 3 Value assessment'!B12 | C6: ='Step 3 Value assessment'!C12 | D6: ='Step 3 Value assessment'!D12 | E6: ='Step 3 Value assessment'!E12 | F6: ='Step 3 Value assessment'!F12 | G6: ='Step 3 Value assessment'!G12 | H6: ='Step 3 Value assessment'!H12
B7: ='Step 3 Value assessment'!B13 | C7: ='Step 3 Value assessment'!C13 | D7: ='Step 3 Value assessment'!D13 | E7: ='Step 3 Value assessment'!E13 | F7: ='Step 3 Value assessment'!F13 | G7: ='Step 3 Value assessment'!G13 | H7: ='Step 3 Value assessment'!H13
B8: ='Step 3 Value assessment'!B14 | C8: ='Step 3 Value assessment'!C14 | D8: ='Step 3 Value assessment'!D14 | E8: ='Step 3 Value assessment'!E14 | F8: ='Step 3 Value assessment'!F14 | G8: ='Step 3 Value assessment'!G14 | H8: ='Step 3 Value assessment'!H14
B9: ='Step 3 Value assessment'!B15 | C9: ='Step 3 Value assessment'!C15 | D9: ='Step 3 Value assessment'!D15 | E9: ='Step 3 Value assessment'!E15 | F9: ='Step 3 Value assessment'!F15 | G9: ='Step 3 Value assessment'!G15 | H9: ='Step 3 Value assessment'!H15
B10: ='Step 3 Value assessment'!B16 | C10: ='Step 3 Value assessment'!C16 | D10: ='Step 3 Value assessment'!D16 | E10: ='Step 3 Value assessment'!E16 | F10: ='Step 3 Value assessment'!F16 | G10: ='Step 3 Value assessment'!G16 | H10: ='Step 3 Value assessment'!H16
B12: Scoring
B13: Rank | C13: Percentage | D13: =D2 | E13: =E2 | F13: =F2 | G13: =G2 | H13: =H2
B14: 1 | C14: 0.195 | D14: =D3*$C14 | E14: =E3*$C14 | F14: =F3*$C14 | G14: =G3*$C14 | H14: =H3*$C14
B15: 2 | C15: 0.175 | D15: =D4*$C15 | E15: =E4*$C15 | F15: =F4*$C15 | G15: =G4*$C15 | H15: =H4*$C15
B16: 3 | C16: 0.155 | D16: =D5*$C16 | E16: =E5*$C16 | F16: =F5*$C16 | G16: =G5*$C16 | H16: =H5*$C16
B17: 4 | C17: 0.135 | D17: =D6*$C17 | E17: =E6*$C17 | F17: =F6*$C17 | G17: =G6*$C17 | H17: =H6*$C17
B18: 5 | C18: 0.115 | D18: =D7*$C18 | E18: =E7*$C18 | F18: =F7*$C18 | G18: =G7*$C18 | H18: =H7*$C18
B19: 6 | C19: 0.095 | D19: =D8*$C19 | E19: =E8*$C19 | F19: =F8*$C19 | G19: =G8*$C19 | H19: =H8*$C19
B20: 7 | C20: 0.075 | D20: =D9*$C20 | E20: =E9*$C20 | F20: =F9*$C20 | G20: =G9*$C20 | H20: =H9*$C20
B21: 8 | C21: 0.055 | D21: =D10*$C21 | E21: =E10*$C21 | F21: =F10*$C21 | G21: =G10*$C21 | H21: =H10*$C21 | K21: Min | L21: Max
B22: Total | C22: =SUM(C14:C21) | D22: =IF(D13<>"",SUM(D14:D21),NA()) | E22: =IF(E13<>"",SUM(E14:E21),NA()) | F22: =IF(F13<>"",SUM(F14:F21),NA()) | G22: =IF(G13<>"",SUM(G14:G21),NA()) | H22: =IF(H13<>"",SUM(H14:H21),NA()) | K22: -2 | L22: 2
B23: Adj | D23: =(D22+2)/4*100 | E23: =(E22+2)/4*100 | F23: =(F22+2)/4*100 | G23: =(G22+2)/4*100 | H23: =(H22+2)/4*100
B25: Prices
D26: =D2 | E26: =E2 | F26: =F2 | G26: =G2 | H26: =H2 | I26: =I2 | K26: Min | L26: Max
C27: Price | D27: =IF(D26<>"",IF('Step 2 competition'!$C$14>0,'Step 2 competition'!C18/'Step 2 competition'!$C$14,""),"") | E27: =IF(E26<>"",IF('Step 2 competition'!$C$14>0,'Step 2 competition'!C19/'Step 2 competition'!$C$14,""),"") | F27: =IF(F26<>"",IF('Step 2 competition'!$C$14>0,'Step 2 competition'!C20/'Step 2 competition'!$C$14,""),"") | G27: =IF(G26<>"",IF('Step 2 competition'!$C$14>0,'Step 2 competition'!C21/'Step 2 competition'!$C$14,""),"") | H27: =IF(H26<>"",IF('Step 2 competition'!$C$14>0,'Step 2 competition'!C22/'Step 2 competition'!$C$14,""),"") | I27: =IF(I26<>"",IF('Step 2 competition'!$C$14>0,'Step 2 competition'!C23/'Step 2 competition'!$C$14,""),"") | K27: =MIN($D$27:$I$27) | L27: =MAX($D$27:$I$27)
C30: Competitors | D30: Price | E30: Market share | F30: Value score | G30: Value score adj | H30: PPV | I30: Weigh PPV | J30: Calculated price
B31: 1 | C31: =IF(D13<>"",D13,"") | D31: =IF(_xlfn.XLOOKUP($C31,'Step 2 competition'!$B$18:$B$23,'Step 2 competition'!$C$18:$C$23,"",0)="","",IF('Step 2 competition'!$C$14>0,_xlfn.XLOOKUP($C31,'Step 2 competition'!$B$18:$B$23,'Step 2 competition'!$C$18:$C$23,"",0)/'Step 2 competition'!$C$14,"")) | E31: =_xlfn.XLOOKUP($C31,'Step 2 competition'!$B$29:$B$34,'Step 2 competition'!$C$29:$C$34,"",0) | F31: =IF(C31<>"",_xlfn.XLOOKUP(C31,$D$13:$I$13,$D$22:$I$22,"",0),"") | G31: =IF(C31<>"",(F31+2)/4*100,"") | H31: =IF(C31<>"",D31/G31,"") | I31: =IF(C31<>"",H31*E31,"") | J31: {=_xlfn.LET( _xlpm.p, $D$31:$D$36, _xlpm.s, $E$31:$E$36, _xlpm.v, $G$31:$G$36, _xlpm.sdec, IF(MAX(_xlpm.s)>1, _xlpm.s/100, _xlpm.s), _xlpm.wsum, SUM(_xlpm.sdec), _xlpm.marketP, IF(_xlpm.wsum=0, NA(), SUMPRODUCT(_xlpm.p, _xlpm.sdec)/_xlpm.wsum), _xlpm.marketV, IF(_xlpm.wsum=0, NA(), SUMPRODUCT(_xlpm.v, _xlpm.sdec)/_xlpm.wsum), _xlpm.floorPct, $B$45, _xlpm.pmax, MAX(_xlpm.p), _xlpm.floorP, _xlpm.floorPct * _xlpm.pmax, _xlpm.slope, IF(_xlpm.marketV=0, NA(), (_xlpm.marketP - _xlpm.floorP) / _xlpm.marketV), _xlpm.floorP + _xlpm.slope * INDEX(_xlpm.v, ROW()-30) )}
B32: 2 | C32: =IF(E13<>"",E13,"") | D32: =IF(_xlfn.XLOOKUP($C32,'Step 2 competition'!$B$18:$B$23,'Step 2 competition'!$C$18:$C$23,"",0)="","",IF('Step 2 competition'!$C$14>0,_xlfn.XLOOKUP($C32,'Step 2 competition'!$B$18:$B$23,'Step 2 competition'!$C$18:$C$23,"",0)/'Step 2 competition'!$C$14,"")) | E32: =_xlfn.XLOOKUP($C32,'Step 2 competition'!$B$29:$B$34,'Step 2 competition'!$C$29:$C$34,"",0) | F32: =IF(C32<>"",_xlfn.XLOOKUP(C32,$D$13:$I$13,$D$22:$I$22,"",0),"") | G32: =IF(C32<>"",(F32+2)/4*100,"") | H32: =IF(C32<>"",D32/G32,"") | I32: =IF(C32<>"",H32*E32,"") | J32: {=_xlfn.LET( _xlpm.p, $D$31:$D$36, _xlpm.s, $E$31:$E$36, _xlpm.v, $G$31:$G$36, _xlpm.sdec, IF(MAX(_xlpm.s)>1, _xlpm.s/100, _xlpm.s), _xlpm.wsum, SUM(_xlpm.sdec), _xlpm.marketP, IF(_xlpm.wsum=0, NA(), SUMPRODUCT(_xlpm.p, _xlpm.sdec)/_xlpm.wsum), _xlpm.marketV, IF(_xlpm.wsum=0, NA(), SUMPRODUCT(_xlpm.v, _xlpm.sdec)/_xlpm.wsum), _xlpm.floorPct, $B$45, _xlpm.pmax, MAX(_xlpm.p), _xlpm.floorP, _xlpm.floorPct * _xlpm.pmax, _xlpm.slope, IF(_xlpm.marketV=0, NA(), (_xlpm.marketP - _xlpm.floorP) / _xlpm.marketV), _xlpm.floorP + _xlpm.slope * INDEX(_xlpm.v, ROW()-30) )}
B33: 3 | C33: =IF(F13<>"",F13,"") | D33: =IF(_xlfn.XLOOKUP($C33,'Step 2 competition'!$B$18:$B$23,'Step 2 competition'!$C$18:$C$23,"",0)="","",IF('Step 2 competition'!$C$14>0,_xlfn.XLOOKUP($C33,'Step 2 competition'!$B$18:$B$23,'Step 2 competition'!$C$18:$C$23,"",0)/'Step 2 competition'!$C$14,"")) | E33: =_xlfn.XLOOKUP($C33,'Step 2 competition'!$B$29:$B$34,'Step 2 competition'!$C$29:$C$34,"",0) | F33: =IF(C33<>"",_xlfn.XLOOKUP(C33,$D$13:$I$13,$D$22:$I$22,"",0),"") | G33: =IF(C33<>"",(F33+2)/4*100,"") | H33: =IF(C33<>"",D33/G33,"") | I33: =IF(C33<>"",H33*E33,"") | J33: {=_xlfn.LET( _xlpm.p, $D$31:$D$36, _xlpm.s, $E$31:$E$36, _xlpm.v, $G$31:$G$36, _xlpm.sdec, IF(MAX(_xlpm.s)>1, _xlpm.s/100, _xlpm.s), _xlpm.wsum, SUM(_xlpm.sdec), _xlpm.marketP, IF(_xlpm.wsum=0, NA(), SUMPRODUCT(_xlpm.p, _xlpm.sdec)/_xlpm.wsum), _xlpm.marketV, IF(_xlpm.wsum=0, NA(), SUMPRODUCT(_xlpm.v, _xlpm.sdec)/_xlpm.wsum), _xlpm.floorPct, $B$45, _xlpm.pmax, MAX(_xlpm.p), _xlpm.floorP, _xlpm.floorPct * _xlpm.pmax, _xlpm.slope, IF(_xlpm.marketV=0, NA(), (_xlpm.marketP - _xlpm.floorP) / _xlpm.marketV), _xlpm.floorP + _xlpm.slope * INDEX(_xlpm.v, ROW()-30) )}
B34: 4 | C34: =IF(G13<>"",G13,"") | D34: =IF(_xlfn.XLOOKUP($C34,'Step 2 competition'!$B$18:$B$23,'Step 2 competition'!$C$18:$C$23,"",0)="","",IF('Step 2 competition'!$C$14>0,_xlfn.XLOOKUP($C34,'Step 2 competition'!$B$18:$B$23,'Step 2 competition'!$C$18:$C$23,"",0)/'Step 2 competition'!$C$14,"")) | E34: =_xlfn.XLOOKUP($C34,'Step 2 competition'!$B$29:$B$34,'Step 2 competition'!$C$29:$C$34,"",0) | F34: =IF(C34<>"",_xlfn.XLOOKUP(C34,$D$13:$I$13,$D$22:$I$22,"",0),"") | G34: =IF(C34<>"",(F34+2)/4*100,"") | H34: =IF(C34<>"",D34/G34,"") | I34: =IF(C34<>"",H34*E34,"") | J34: {=_xlfn.LET( _xlpm.p, $D$31:$D$36, _xlpm.s, $E$31:$E$36, _xlpm.v, $G$31:$G$36, _xlpm.sdec, IF(MAX(_xlpm.s)>1, _xlpm.s/100, _xlpm.s), _xlpm.wsum, SUM(_xlpm.sdec), _xlpm.marketP, IF(_xlpm.wsum=0, NA(), SUMPRODUCT(_xlpm.p, _xlpm.sdec)/_xlpm.wsum), _xlpm.marketV, IF(_xlpm.wsum=0, NA(), SUMPRODUCT(_xlpm.v, _xlpm.sdec)/_xlpm.wsum), _xlpm.floorPct, $B$45, _xlpm.pmax, MAX(_xlpm.p), _xlpm.floorP, _xlpm.floorPct * _xlpm.pmax, _xlpm.slope, IF(_xlpm.marketV=0, NA(), (_xlpm.marketP - _xlpm.floorP) / _xlpm.marketV), _xlpm.floorP + _xlpm.slope * INDEX(_xlpm.v, ROW()-30) )}
B35: 5 | C35: =IF(H13<>"",H13,"") | D35: =IF(_xlfn.XLOOKUP($C35,'Step 2 competition'!$B$18:$B$23,'Step 2 competition'!$C$18:$C$23,"",0)="","",IF('Step 2 competition'!$C$14>0,_xlfn.XLOOKUP($C35,'Step 2 competition'!$B$18:$B$23,'Step 2 competition'!$C$18:$C$23,"",0)/'Step 2 competition'!$C$14,"")) | E35: =_xlfn.XLOOKUP($C35,'Step 2 competition'!$B$29:$B$34,'Step 2 competition'!$C$29:$C$34,"",0) | F35: =IF(C35<>"",_xlfn.XLOOKUP(C35,$D$13:$I$13,$D$22:$I$22,"",0),"") | G35: =IF(C35<>"",(F35+2)/4*100,"") | H35: =IF(C35<>"",D35/G35,"") | I35: =IF(C35<>"",H35*E35,"") | J35: {=_xlfn.LET( _xlpm.p, $D$31:$D$36, _xlpm.s, $E$31:$E$36, _xlpm.v, $G$31:$G$36, _xlpm.sdec, IF(MAX(_xlpm.s)>1, _xlpm.s/100, _xlpm.s), _xlpm.wsum, SUM(_xlpm.sdec), _xlpm.marketP, IF(_xlpm.wsum=0, NA(), SUMPRODUCT(_xlpm.p, _xlpm.sdec)/_xlpm.wsum), _xlpm.marketV, IF(_xlpm.wsum=0, NA(), SUMPRODUCT(_xlpm.v, _xlpm.sdec)/_xlpm.wsum), _xlpm.floorPct, $B$45, _xlpm.pmax, MAX(_xlpm.p), _xlpm.floorP, _xlpm.floorPct * _xlpm.pmax, _xlpm.slope, IF(_xlpm.marketV=0, NA(), (_xlpm.marketP - _xlpm.floorP) / _xlpm.marketV), _xlpm.floorP + _xlpm.slope * INDEX(_xlpm.v, ROW()-30) )}
B36: 6 | C36: =IF(I13<>"",I13,"") | D36: =IF(_xlfn.XLOOKUP($C36,'Step 2 competition'!$B$18:$B$23,'Step 2 competition'!$C$18:$C$23,"",0)="","",IF('Step 2 competition'!$C$14>0,_xlfn.XLOOKUP($C36,'Step 2 competition'!$B$18:$B$23,'Step 2 competition'!$C$18:$C$23,"",0)/'Step 2 competition'!$C$14,"")) | E36: =IF(_xlfn.XLOOKUP($C36,'Step 2 competition'!$B$29:$B$34,'Step 2 competition'!$C$29:$C$34,"",0)=0,"",_xlfn.XLOOKUP($C36,'Step 2 competition'!$B$29:$B$34,'Step 2 competition'!$C$29:$C$34,"",0)) | F36: =IF(C36<>"",_xlfn.XLOOKUP(C36,$D$13:$I$13,$D$22:$I$22,"",0),"") | G36: =IF(C36<>"",(F36+2)/4*100,"") | H36: =IF(C36<>"",D36/G36,"") | I36: =IF(C36<>"",H36*E36,"") | J36: {=_xlfn.LET( _xlpm.p, $D$31:$D$36, _xlpm.s, $E$31:$E$36, _xlpm.v, $G$31:$G$36, _xlpm.sdec, IF(MAX(_xlpm.s)>1, _xlpm.s/100, _xlpm.s), _xlpm.wsum, SUM(_xlpm.sdec), _xlpm.marketP, IF(_xlpm.wsum=0, NA(), SUMPRODUCT(_xlpm.p, _xlpm.sdec)/_xlpm.wsum), _xlpm.marketV, IF(_xlpm.wsum=0, NA(), SUMPRODUCT(_xlpm.v, _xlpm.sdec)/_xlpm.wsum), _xlpm.floorPct, $B$45, _xlpm.pmax, MAX(_xlpm.p), _xlpm.floorP, _xlpm.floorPct * _xlpm.pmax, _xlpm.slope, IF(_xlpm.marketV=0, NA(), (_xlpm.marketP - _xlpm.floorP) / _xlpm.marketV), _xlpm.floorP + _xlpm.slope * INDEX(_xlpm.v, ROW()-30) )}
B38: Market-weighted average price | D38: Market-weighted average value
B39: =SUMPRODUCT(D31:D36,E31:E36)/SUM(E31:E36) | D39: =SUMPRODUCT(E31:E36,G31:G36)/SUM(E31:E36)
F40: Anchor line
B41: Min value | C41: Max value | D41: Value range | F41: Min | G41: Mid | J41: =F42 | K41: =G42
B42: =MIN(G32:G36) | C42: =MAX(G32:G36) | D42: =C42-B42 | F42: =MIN($F$31:$F$36) | G42: =MIN($D$31:$D$36) | J42: =F43 | K42: =G43
F43: =MAX($F$31:$F$36) | G43: =MAX($D$31:$D$36) | J43: 0
B44: Floor price level | C44: Floor price | D44: Max Price | J44: 0
B45: 0.7 | C45: =MAX(D32:D36)*B45 | D45: =MAX(D32:D36) | J45: 0
...

Sheet 2024 Revenue
A1: Country | B1: Revenue 2024 | C1: Value driver analysis
A2: Australia | B2: 89588268 | C2: X
A3: China | B3: 27604029 | C3: X
A4: India | B4: 24860878 | C4: X
A5: Nepal | B5: 5970381 | C5: O
A6: Canada | B6: 5626341 | C6: O
A7: Pakistan | B7: 5595099 | C7: O
A8: Philippines | B8: 4048257 | C8: X
A9: United Kingdom | B9: 3765606 | C9: O
A10: New Zealand | B10: 3452158 | C10: O
A11: Sri Lanka | B11: 2873716 | C11: X
A12: United Arab Emirates | B12: 2470242 | C12: X
A13: Turkiye | B13: 2147990 | C13: X
... A21: South Africa | B21: 775664 | C21: X
A22: Malaysia | B22: 641977
A23: Qatar | B23: 629027
A24: Egypt | B24: 479114 | C24: X
A25: Thailand | B25: 400153
A26: Fiji | B26: 362270
A27: Indonesia | B27: 348785
A28: Bhutan | B28: 345442
A29: Taiwan | B29: 338770
A30: Kuwait | B30: 333211
A31: Zimbabwe | B31: 306177
A32: Kenya | B32: 282456
A33: Bahrain | B33: 239523
A34: Nigeria | B34: 227681
A35: Brazil | B35: 203241 | C35: O
A36: Japan | B36: 200161
A37: Ireland | B37: 189945
A38: Oman | B38: 164516
A39: Iraq | B39: 161450
A40: Germany | B40: 145440
A41: Jordan | B41: 120135
A42: France | B42: 113825
A43: Spain | B43: 110879
A44: Norway | B44: 109383
A45: Netherlands | B45: 102402
A46: Papua New Guinea | B46: 98996
A47: Israel | B47: 93974
...
