Workbook

Sheet Definitions
B2: Price modelling
B4: Value driver overview
B5: Value driver name | C5: Definition
B6: Brand Awareness | C6: The degree to which customers value a platform’s market reputation and recognition to enhance the credibility and adoption of their credentials
B7: Analytics | C7: The importance customers place on access to actionable data and insights to demonstrate program impact (ROI) and inform decision-making
B8: Ease of Use (Issuer) | C8: The extent to which customers prioritize an intuitive and efficient administrative experience to minimize effort and operational complexity
B9: Customer Support | C9: How reliable and effective buyers perceive the support experience to be in resolving issues and enabling success
B10: Customization | C10: The degree to which buyers feel the platform can be adapted to their specific branding, workflows, and requirements
B11: Ease of Use (Earner) | C11: How simple and intuitive buyers believe the experience is for end users, especially in driving engagement, completion, and sharing
B12: Security | C12: How confident buyers are in the platform’s ability to protect data, ensure compliance, and maintain credential integrity
B15: Market strategies
B16: Name | C16: Definition
B17: Challenger/gain market share | C17: Some markets have currently unrealized potential, due to a currently worse value proposition than the competition or an overall growth in the market. In these markets, pricing lower than the competition/lower than the provided value can help in growing the market share and maximize profitability in the long term.
B18: On par/no special objective | C18: Default option. In competitive markets, products should be priced according to the value they provide and value differences between competitors should be reflected in the prices of products.
B19: Market leader/defend market share | C19: In markets, in which PTE is already in a dominant position but competitors are trying to buy market share, one possible strategy is to price (slightly) lower than the provided value in order to prevent competitors from gaining market share.
B20: Margin skimming | C20: Markets can become less attractive if they are showing signs of a decline of the overall customer base or increasing difficulties of conducting business. In these markets, a premium can be charged in order to maximize profitability from a declining number of customers.
B22: Calculation modifiers
B23: Name | C23: Definition
B24: Market strategies | C24: See definitions above. For each of the strategic market objectives, a positive or negative percentage in-/decrease in price calculation can be added. These determine how aggressively these objectives are followed and need to be defined globally, per region, or per country.
B25: Max contribution per value driver | C25: This modifier defines how high the maximum price in-/decrease can be for a single value driver that has the highest importance and a strong negative or positive performance. The contribution of all other value drivers is derived from this value.
B26: Max total price range | C26: This is calculated directly from the "Max contribution per value driver" and shows how big the maximum achievable price de/-increase would be if all value drivers had the strongest negative/positive performance rating.

Sheet Step 1 VD Relevance
B2: Step 1: Value Driver Relevance
B4: Please specify the market for this exercise: | D4: USA
B5: Please specify the persona for this exercise: | D5: HigherED & Associations
B7: Please rank these value drivers based on their relevance to the test taker
B8: 1 = most important; 7 = least important
B10: Value driver | C10: Rank Final | D10: Rank EP | E10: Rank NG | F10: Rank CW | G10: Rank KL | H10: Rank BG | I10: Workshop avg. rank
B11: Brand Awareness | C11: =RANK(I11,$I$11:$I$17,1) -> 4 | D11: 4 | E11: 5 | H11: 2 | I11: =AVERAGE(D11:H11) -> 3.6666667
B12: Analytics | C12: =RANK(I12,$I$11:$I$17,1) -> 5 | D12: 5 | E12: 6 | H12: 4 | I12: =AVERAGE(D12:H12) -> 5
B13: Ease of Use (Issuer) | C13: =RANK(I13,$I$11:$I$17,1) -> 1 | D13: 1 | E13: 2 | H13: 1 | I13: =AVERAGE(D13:H13) -> 1.3333333
B14: Customer Support | C14: =RANK(I14,$I$11:$I$17,1) -> 3 | D14: 3 | E14: 4 | H14: 3 | I14: =AVERAGE(D14:H14) -> 3.3333333
B15: Customization | C15: =RANK(I15,$I$11:$I$17,1) -> 5 | D15: 7 | E15: 3 | H15: 5 | I15: =AVERAGE(D15:H15) -> 5
B16: Ease of Use (Earner) | C16: =RANK(I16,$I$11:$I$17,1) -> 2 | D16: 2 | E16: 1 | H16: 6 | I16: =AVERAGE(D16:H16) -> 3
B17: Security | C17: =RANK(I17,$I$11:$I$17,1) -> 7 | D17: 6 | E17: 7 | H17: 7 | I17: =AVERAGE(D17:H17) -> 6.6666667
B20: Please make sure to rank all 7 Value Drivers
B21: You are good to go. Please proceed to Step 2.

Sheet Step 2 competition
B2: Step 2: Market Situation
B4: Which are the most relevant competitors in the market? | D4: =AND( COUNTA($C$18:$C$20)=3, COUNTA($C$29:$C$31)=3, OR($B$10="(enter name here)", AND($C$21<>"",$C$32<>"")), OR($B$11="(enter name here)", AND($C$22<>"",$C$33<>"")), OR($B$12="(enter name here)", AND($C$23<>"",$C$34<>"")) ) -> FALSE
B6: Competitor name
B7: Credly
B8: Accredible
B9: Parchment
B10: Canvas
B11: Territorium
B12: (enter name here)
B15: Fill in the prices (in USD) of the competitors you added
B17: Competitor name | C17: Price
B18: =IF(B7="(enter name here)","",B7) -> Credly
B19: =IF(B8="(enter name here)","",B8) -> Accredible
B20: =IF(B9="(enter name here)","",B9) -> Parchment
B21: =IF(B10="(enter name here)","",B10) -> Canvas
B22: =IF(B11="(enter name here)","",B11) -> Territorium
B23: =IF(B12="(enter name here)","",B12)
B26: Please give an estimate of the relative market share of each competitor
B28: Competitor name | C28: Market share
B29: =IF(B7="(enter name here)","",B7) -> Credly
B30: =IF(B8="(enter name here)","",B8) -> Accredible
B31: =IF(B9="(enter name here)","",B9) -> Parchment
B32: =IF(B10="(enter name here)","",B10) -> Canvas
B33: =IF(B11="(enter name here)","",B11) -> Territorium
B34: =IF(B12="(enter name here)","",B12)
B36: Please fill in a price and market share for all relevant competitors
B37: You are good to go. Please proceed to Step 3.

Sheet Step 3 Value assessment
B2: Step 3: Competition Value Assessment
B4: Please evaluate each competitor's performance on each of the value drivers from -2 to +2 | H4: =AND( COUNTA($D$9:$F$15)=ROWS($D$9:$F$15)*COLUMNS($D$9:$F$15), OR($G$8="",COUNTA($G$9:$G$15)=ROWS($G$9:$G$15)), OR($H$8="",COUNTA($H$9:$H$15)=ROWS($H$9:$H$15)), OR($I$8="",COUNTA($I$9:$I$15)=ROWS($I$9:$I$15)) ) -> TRUE
B5: 0 = market average; 2 = leading the market; -2 = significantly lacking
I7: EP | M7: NG | Q7: CW | U7: KL | Y7: BG
B8: Rank | C8: Value driver name | D8: =IF('Step 2 competition'!B7="(enter name here)","",'Step 2 competition'!B7) -> Credly | E8: =IF('Step 2 competition'!B8="(enter name here)","",'Step 2 competition'!B8) -> Accredible | F8: =IF('Step 2 competition'!B9="(enter name here)","",'Step 2 competition'!B9) -> Parchment | G8: =IF('Step 2 competition'!B10="(enter name here)","",'Step 2 competition'!B10) -> Canvas | H8: =IF('Step 2 competition'!B11="(enter name here)","",'Step 2 competition'!B11) -> Territorium | I8: Credly | J8: Accredible | L8: Canvas | M8: Credly | N8: Accredible | O8: Parchment | Q8: Credly | U8: Credly | Y8: Credly | Z8: Accredible | AB8: Canvas | AC8: Territorium
B9: 1 | C9: =_xlfn.XLOOKUP(B9,'Step 1 VD Relevance'!$C$11:$C$18,'Step 1 VD Relevance'!$B$11:$B$18,"",0) -> Ease of Use (Issuer) | D9: =AVERAGE(I9,M9,Q9,U9,Y9) -> 0.5 | E9: =AVERAGE(J9,N9,R9,V9,Z9) -> 0.33333333 | F9: =AVERAGE(K9,O9,S9,W9,AA9) -> 0 | G9: =AVERAGE(L9,P9,T9,X9,AB9) -> 1.5 | H9: =AC9 -> -1 | I9: 2 | J9: 0 | L9: 1 | M9: -1 | N9: 1 | O9: 0 | Z9: 0 | AB9: 2 | AC9: -1
B10: 2 | C10: =_xlfn.XLOOKUP(B10,'Step 1 VD Relevance'!$C$11:$C$18,'Step 1 VD Relevance'!$B$11:$B$18,"",0) -> Ease of Use (Earner) | D10: =AVERAGE(I10,M10,Q10,U10,Y10) -> 0.5 | E10: =AVERAGE(J10,N10,R10,V10,Z10) -> 1.3333333 | F10: =AVERAGE(K10,O10,S10,W10,AA10) -> 1 | G10: =AVERAGE(L10,P10,T10,X10,AB10) -> 0 | H10: =AC10 -> -2 | I10: 0 | J10: 1 | L10: 0 | M10: 1 | N10: 1 | O10: 1 | Z10: 2 | AB10: 0 | AC10: -2
B11: 3 | C11: =_xlfn.XLOOKUP(B11,'Step 1 VD Relevance'!$C$11:$C$18,'Step 1 VD Relevance'!$B$11:$B$18,"",0) -> Customer Support | D11: =AVERAGE(I11,M11,Q11,U11,Y11) -> 1.5 | E11: =AVERAGE(J11,N11,R11,V11,Z11) -> -0.33333333 | F11: =AVERAGE(K11,O11,S11,W11,AA11) -> 1 | G11: =AVERAGE(L11,P11,T11,X11,AB11) -> 0 | H11: =AC11 -> 1 | I11: 2 | J11: -1 | L11: 1 | M11: 1 | N11: 1 | O11: 1 | Z11: -1 | AB11: -1 | AC11: 1
B12: 4 | C12: =_xlfn.XLOOKUP(B12,'Step 1 VD Relevance'!$C$11:$C$18,'Step 1 VD Relevance'!$B$11:$B$18,"",0) -> Brand Awareness | D12: =AVERAGE(I12,M12,Q12,U12,Y12) -> 2 | E12: =AVERAGE(J12,N12,R12,V12,Z12) -> 0.33333333 | F12: =AVERAGE(K12,O12,S12,W12,AA12) -> 1 | G12: =AVERAGE(L12,P12,T12,X12,AB12) -> 0.5 | H12: =AC12 -> 0 | I12: 2 | J12: 1 | L12: 1 | M12: 2 | N12: 0 | O12: 1 | Z12: 0 | AB12: 0 | AC12: 0
B13: 5 | C13: =_xlfn.XLOOKUP(B13,'Step 1 VD Relevance'!$C$11:$C$18,'Step 1 VD Relevance'!$B$11:$B$18,"",0) -> Analytics | D13: =AVERAGE(I13,M13,Q13,U13,Y13) -> 1 | E13: =AVERAGE(J13,N13,R13,V13,Z13) -> 0.66666667 | F13: =AVERAGE(K13,O13,S13,W13,AA13) -> 1 | G13: =AVERAGE(L13,P13,T13,X13,AB13) -> -0.5 | H13: =AC13 -> 1 | I13: 0 | J13: 0 | L13: -1 | M13: 2 | N13: 0 | O13: 1 | Z13: 2 | AB13: 0 | AC13: 1
B14: 6 | C14: =_xlfn.XLOOKUP(B14,'Step 1 VD Relevance'!$C$11:$C$18,'Step 1 VD Relevance'!$B$11:$B$18,"",0) | D14: =AVERAGE(I14,M14,Q14,U14,Y14) -> 1 | E14: =AVERAGE(J14,N14,R14,V14,Z14) -> 0 | F14: =AVERAGE(K14,O14,S14,W14,AA14) -> 0 | G14: =AVERAGE(L14,P14,T14,X14,AB14) -> 1 | H14: =AC14 -> 0 | I14: 2 | J14: -1 | L14: 0 | M14: 0 | N14: 0 | O14: 0 | Z14: 1 | AB14: 2 | AC14: 0
B15: 7 | C15: =_xlfn.XLOOKUP(B15,'Step 1 VD Relevance'!$C$11:$C$18,'Step 1 VD Relevance'!$B$11:$B$18,"",0) -> Security | D15: =AVERAGE(I15,M15,Q15,U15,Y15) -> 1 | E15: =AVERAGE(J15,N15,R15,V15,Z15) -> 0.16666667 | F15: =AVERAGE(K15,O15,S15,W15,AA15) -> 1 | G15: =AVERAGE(L15,P15,T15,X15,AB15) -> 0.5 | H15: =AC15 -> 0 | I15: 0 | J15: 1.5 | L15: 1 | M15: 2 | N15: -1 | O15: 1 | Z15: 0 | AB15: 0 | AC15: 0
B18: Please assess the performance for all value drivers for all relevant competitors.

Sheet Step 4 Results
B2: Step 4: Results and Price Recommendation
B4: Market: | C4: ='Step 1 VD Relevance'!D4 -> USA | E4: Current market leader: | F4: =INDEX('Step 2 competition'!$B$29:$B$33, MATCH(MAX('Step 2 competition'!$C$29:$C$33), 'Step 2 competition'!$C$29:$C$33, 0)) -> #N/A
B5: 2024 revenue (USD): | C5: =_xlfn.XLOOKUP(C4,'2024 Revenue'!$A$2:$A$175,'2024 Revenue'!$B$2:$B$175,"",0) | E5: Current Credly market share | F5: ='Step 2 competition'!C29 -> 0
B31: Competitor | C31: =IF(Calculations!D26<>"",Calculations!D26,"") -> Credly | D31: =IF(Calculations!E26<>"",Calculations!E26,"") -> Accredible | E31: =IF(Calculations!F26<>"",Calculations!F26,"") -> Parchment | F31: =IF(Calculations!G26<>"",Calculations!G26,"") -> Canvas | G31: =IF(Calculations!H26<>"",Calculations!H26,"") -> Territorium | H31: =IF(Calculations!I26<>"",Calculations!I26,"") -> Credly
B32: Value Score | C32: =IF(C31<>"",_xlfn.XLOOKUP(C31,Calculations!$D$13:$I$13,Calculations!$D$23:$I$23,"",0),"") -> 74.3125 | D32: =IF(D31<>"",_xlfn.XLOOKUP(D31,Calculations!$D$13:$I$13,Calculations!$D$23:$I$23,"",0),"") -> 59.520833 | E32: =IF(E31<>"",_xlfn.XLOOKUP(E31,Calculations!$D$13:$I$13,Calculations!$D$23:$I$23,"",0),"") -> 66.375 | F32: =IF(F31<>"",_xlfn.XLOOKUP(F31,Calculations!$D$13:$I$13,Calculations!$D$23:$I$23,"",0),"") -> 60.875 | G32: =IF(G31<>"",_xlfn.XLOOKUP(G31,Calculations!$D$13:$I$13,Calculations!$D$23:$I$23,"",0),"") -> 43.125 | H32: =IF(H31<>"",_xlfn.XLOOKUP(H31,Calculations!$D$13:$I$13,Calculations!$D$23:$I$23,"",0),"") -> 74.3125
B33: Price | C33: =IF(C31<>"",_xlfn.XLOOKUP('Step 4 Results'!C31,Calculations!$D$26:$I$26,Calculations!$D$27:$I$27,"",0),"") -> 0 | D33: =IF(D31<>"",_xlfn.XLOOKUP('Step 4 Results'!D31,Calculations!$D$26:$I$26,Calculations!$D$27:$I$27,"",0),"") -> 0 | E33: =IF(E31<>"",_xlfn.XLOOKUP('Step 4 Results'!E31,Calculations!$D$26:$I$26,Calculations!$D$27:$I$27,"",0),"") -> 0 | F33: =IF(F31<>"",_xlfn.XLOOKUP('Step 4 Results'!F31,Calculations!$D$26:$I$26,Calculations!$D$27:$I$27,"",0),"") -> 0 | G33: =IF(G31<>"",_xlfn.XLOOKUP('Step 4 Results'!G31,Calculations!$D$26:$I$26,Calculations!$D$27:$I$27,"",0),"") -> 0 | H33: =IF(H31<>"",_xlfn.XLOOKUP('Step 4 Results'!H31,Calculations!$D$26:$I$26,Calculations!$D$27:$I$27,"",0),"") -> 0
B34: Price per Value | C34: =IF(C31<>"",_xlfn.XLOOKUP('Step 4 Results'!C31,Calculations!$C$31:$C$36,Calculations!$H$31:$H$36,"",0),"") -> 0 | D34: =IF(D31<>"",_xlfn.XLOOKUP('Step 4 Results'!D31,Calculations!$C$31:$C$36,Calculations!$H$31:$H$36,"",0),"") -> 0 | E34: =IF(E31<>"",_xlfn.XLOOKUP('Step 4 Results'!E31,Calculations!$C$31:$C$36,Calculations!$H$31:$H$36,"",0),"") -> 0 | F34: =IF(F31<>"",_xlfn.XLOOKUP('Step 4 Results'!F31,Calculations!$C$31:$C$36,Calculations!$H$31:$H$36,"",0),"") -> 0 | G34: =IF(G31<>"",_xlfn.XLOOKUP('Step 4 Results'!G31,Calculations!$C$31:$C$36,Calculations!$H$31:$H$36,"",0),"") -> 0 | H34: =IF(H31<>"",_xlfn.XLOOKUP('Step 4 Results'!H31,Calculations!$C$31:$C$36,Calculations!$H$31:$H$36,"",0),"") -> 0
B37: Recommended Price range | E37: USD | F37: =Calculations!B54 -> #N/A

Sheet Calculations
B1: Results
B2: ='Step 3 Value assessment'!B8 -> Rank | C2: ='Step 3 Value assessment'!C8 -> Value driver name | D2: ='Step 3 Value assessment'!D8 -> Credly | E2: ='Step 3 Value assessment'!E8 -> Accredible | F2: ='Step 3 Value assessment'!F8 -> Parchment | G2: ='Step 3 Value assessment'!G8 -> Canvas | H2: ='Step 3 Value assessment'!H8 -> Territorium | I2: ='Step 3 Value assessment'!I8 -> Credly
B3: ='Step 3 Value assessment'!B9 -> 1 | C3: ='Step 3 Value assessment'!C9 -> Ease of Use (Issuer) | D3: ='Step 3 Value assessment'!D9 -> 0.5 | E3: ='Step 3 Value assessment'!E9 -> 0.33333333 | F3: ='Step 3 Value assessment'!F9 -> 0 | G3: ='Step 3 Value assessment'!G9 -> 1.5 | H3: ='Step 3 Value assessment'!H9 -> -1 | I3: ='Step 3 Value assessment'!I9 -> 2
B4: ='Step 3 Value assessment'!B10 -> 2 | C4: ='Step 3 Value assessment'!C10 -> Ease of Use (Earner) | D4: ='Step 3 Value assessment'!D10 -> 0.5 | E4: ='Step 3 Value assessment'!E10 -> 1.3333333 | F4: ='Step 3 Value assessment'!F10 -> 1 | G4: ='Step 3 Value assessment'!G10 -> 0 | H4: ='Step 3 Value assessment'!H10 -> -2 | I4: ='Step 3 Value assessment'!I10 -> 0
B5: ='Step 3 Value assessment'!B11 -> 3 | C5: ='Step 3 Value assessment'!C11 -> Customer Support | D5: ='Step 3 Value assessment'!D11 -> 1.5 | E5: ='Step 3 Value assessment'!E11 -> -0.33333333 | F5: ='Step 3 Value assessment'!F11 -> 1 | G5: ='Step 3 Value assessment'!G11 -> 0 | H5: ='Step 3 Value assessment'!H11 -> 1 | I5: ='Step 3 Value assessment'!I11 -> 2
B6: ='Step 3 Value assessment'!B12 -> 4 | C6: ='Step 3 Value assessment'!C12 -> Brand Awareness | D6: ='Step 3 Value assessment'!D12 -> 2 | E6: ='Step 3 Value assessment'!E12 -> 0.33333333 | F6: ='Step 3 Value assessment'!F12 -> 1 | G6: ='Step 3 Value assessment'!G12 -> 0.5 | H6: ='Step 3 Value assessment'!H12 -> 0 | I6: ='Step 3 Value assessment'!I12 -> 2
B7: ='Step 3 Value assessment'!B13 -> 5 | C7: ='Step 3 Value assessment'!C13 -> Analytics | D7: ='Step 3 Value assessment'!D13 -> 1 | E7: ='Step 3 Value assessment'!E13 -> 0.66666667 | F7: ='Step 3 Value assessment'!F13 -> 1 | G7: ='Step 3 Value assessment'!G13 -> -0.5 | H7: ='Step 3 Value assessment'!H13 -> 1 | I7: ='Step 3 Value assessment'!I13 -> 0
B8: ='Step 3 Value assessment'!B14 -> 6 | C8: ='Step 3 Value assessment'!C14 | D8: ='Step 3 Value assessment'!D14 -> 1 | E8: ='Step 3 Value assessment'!E14 -> 0 | F8: ='Step 3 Value assessment'!F14 -> 0 | G8: ='Step 3 Value assessment'!G14 -> 1 | H8: ='Step 3 Value assessment'!H14 -> 0 | I8: ='Step 3 Value assessment'!I14 -> 2
B9: ='Step 3 Value assessment'!B15 -> 7 | C9: ='Step 3 Value assessment'!C15 -> Security | D9: ='Step 3 Value assessment'!D15 -> 1 | E9: ='Step 3 Value assessment'!E15 -> 0.16666667 | F9: ='Step 3 Value assessment'!F15 -> 1 | G9: ='Step 3 Value assessment'!G15 -> 0.5 | H9: ='Step 3 Value assessment'!H15 -> 0 | I9: ='Step 3 Value assessment'!I15 -> 0
B10: ='Step 3 Value assessment'!B16 -> 0 | C10: ='Step 3 Value assessment'!C16 -> 0 | D10: ='Step 3 Value assessment'!D16 -> 0 | E10: ='Step 3 Value assessment'!E16 -> 0 | F10: ='Step 3 Value assessment'!F16 -> 0 | G10: ='Step 3 Value assessment'!G16 -> 0 | H10: ='Step 3 Value assessment'!H16 -> 0 | I10: ='Step 3 Value assessment'!I16 -> 0
B12: Scoring
B13: Rank | C13: Percentage | D13: =D2 -> Credly | E13: =E2 -> Accredible | F13: =F2 -> Parchment | G13: =G2 -> Canvas | H13: =H2 -> Territorium | I13: =I2 -> Credly
B14: 1 | C14: 0.195 | D14: =D3*$C14 -> 0.0975 | E14: =E3*$C14 -> 0.065 | F14: =F3*$C14 -> 0 | G14: =G3*$C14 -> 0.2925 | H14: =H3*$C14 -> -0.195 | I14: =I3*$C14 -> 0.39
B15: 2 | C15: 0.175 | D15: =D4*$C15 -> 0.0875 | E15: =E4*$C15 -> 0.23333333 | F15: =F4*$C15 -> 0.175 | G15: =G4*$C15 -> 0 | H15: =H4*$C15 -> -0.35 | I15: =I4*$C15 -> 0
B16: 3 | C16: 0.155 | D16: =D5*$C16 -> 0.2325 | E16: =E5*$C16 -> -0.051666667 | F16: =F5*$C16 -> 0.155 | G16: =G5*$C16 -> 0 | H16: =H5*$C16 -> 0.155 | I16: =I5*$C16 -> 0.31
B17: 4 | C17: 0.135 | D17: =D6*$C17 -> 0.27 | E17: =E6*$C17 -> 0.045 | F17: =F6*$C17 -> 0.135 | G17: =G6*$C17 -> 0.0675 | H17: =H6*$C17 -> 0 | I17: =I6*$C17 -> 0.27
B18: 5 | C18: 0.115 | D18: =D7*$C18 -> 0.115 | E18: =E7*$C18 -> 0.076666667 | F18: =F7*$C18 -> 0.115 | G18: =G7*$C18 -> -0.0575 | H18: =H7*$C18 -> 0.115 | I18: =I7*$C18 -> 0
B19: 6 | C19: 0.095 | D19: =D8*$C19 -> 0.095 | E19: =E8*$C19 -> 0 | F19: =F8*$C19 -> 0 | G19: =G8*$C19 -> 0.095 | H19: =H8*$C19 -> 0 | I19: =I8*$C19 -> 0.19
B20: 7 | C20: 0.075 | D20: =D9*$C20 -> 0.075 | E20: =E9*$C20 -> 0.0125 | F20: =F9*$C20 -> 0.075 | G20: =G9*$C20 -> 0.0375 | H20: =H9*$C20 -> 0 | I20: =I9*$C20 -> 0
B21: 8 | C21: 0.055 | D21: =D10*$C21 -> 0 | E21: =E10*$C21 -> 0 | F21: =F10*$C21 -> 0 | G21: =G10*$C21 -> 0 | H21: =H10*$C21 -> 0 | I21: =I10*$C21 -> 0 | K21: Min | L21: Max
B22: Total | C22: =SUM(C14:C21) -> 1 | D22: =IF(D13<>"",SUM(D14:D21),NA()) -> 0.9725 | E22: =IF(E13<>"",SUM(E14:E21),NA()) -> 0.38083333 | F22: =IF(F13<>"",SUM(F14:F21),NA()) -> 0.655 | G22: =IF(G13<>"",SUM(G14:G21),NA()) -> 0.435 | H22: =IF(H13<>"",SUM(H14:H21),NA()) -> -0.275 | I22: =IF(I13<>"",SUM(I14:I21),NA()) -> 1.16 | K22: -2 | L22: 2
B23: Adj | D23: =(D22+2)/4*100 -> 74.3125 | E23: =(E22+2)/4*100 -> 59.520833 | F23: =(F22+2)/4*100 -> 66.375 | G23: =(G22+2)/4*100 -> 60.875 | H23: =(H22+2)/4*100 -> 43.125 | I23: =(I22+2)/4*100 -> 79
B25: Prices
D26: =D2 -> Credly | E26: =E2 -> Accredible | F26: =F2 -> Parchment | G26: =G2 -> Canvas | H26: =H2 -> Territorium | I26: =I2 -> Credly | K26: Min | L26: Max
C27: Price | D27: =IF(D26<>"",'Step 2 competition'!C18,"") -> 0 | E27: =IF(E26<>"",'Step 2 competition'!C19,"") -> 0 | F27: =IF(F26<>"",'Step 2 competition'!C20,"") -> 0 | G27: =IF(G26<>"",'Step 2 competition'!C21,"") -> 0 | H27: =IF(H26<>"",'Step 2 competition'!C22,"") -> 0 | I27: =IF(I26<>"",'Step 2 competition'!C23,"") -> 0 | K27: =MIN($D$27:$I$27)-10 -> -10 | L27: =MAX($D$27:$I$27)+10 -> 10
C30: Competitors | D30: Price | E30: Market share | F30: Value score | G30: Value score adj | H30: PPV | I30: Weigh PPV | J30: Calculated price
B31: 1 | C31: =IF(D13<>"",D13,"") -> Credly | D31: =_xlfn.XLOOKUP($C31,'Step 2 competition'!$B$18:$B$23,'Step 2 competition'!$C$18:$C$23,"",0) -> 0 | E31: =_xlfn.XLOOKUP($C31,'Step 2 competition'!$B$29:$B$34,'Step 2 competition'!$C$29:$C$34,"",0) -> 0 | F31: =IF(C31<>"",_xlfn.XLOOKUP(C31,$D$13:$I$13,$D$22:$I$22,"",0),"") -> 0.9725 | G31: =IF(C31<>"",(F31+2)/4*100,"") -> 74.3125 | H31: =IF(C31<>"",D31/G31,"") -> 0 | I31: =IF(C31<>"",H31*E31,"") -> 0 | J31: {=_xlfn.LET( _xlpm.p, $D$31:$D$36, _xlpm.s, $E$31:$E$36, _xlpm.v, $G$31:$G$36, _xlpm.sdec, IF(MAX(_xlpm.s)>1, _xlpm.s/100, _xlpm.s), _xlpm.wsum, SUM(_xlpm.sdec), _xlpm.marketP, IF(_xlpm.wsum=0, NA(), SUMPRODUCT(_xlpm.p, _xlpm.sdec)/_xlpm.wsum), _xlpm.marketV, IF(_xlpm.wsum=0, NA(), SUMPRODUCT(_xlpm.v, _xlpm.sdec)/_xlpm.wsum), _xlpm.floorPct, $B$45, _xlpm.pmax, MAX(_xlpm.p), _xlpm.floorP, _xlpm.floorPct * _xlpm.pmax, _xlpm.slope, IF(_xlpm.marketV=0, NA(), (_xlpm.marketP - _xlpm.floorP) / _xlpm.marketV), _xlpm.floorP + _xlpm.slope * INDEX(_xlpm.v, ROW()-30) )} -> #N/A
B32: 2 | C32: =IF(E13<>"",E13,"") -> Accredible | D32: =_xlfn.XLOOKUP($C32,'Step 2 competition'!$B$18:$B$23,'Step 2 competition'!$C$18:$C$23,"",0) -> 0 | E32: =_xlfn.XLOOKUP($C32,'Step 2 competition'!$B$29:$B$34,'Step 2 competition'!$C$29:$C$34,"",0) -> 0 | F32: =IF(C32<>"",_xlfn.XLOOKUP(C32,$D$13:$I$13,$D$22:$I$22,"",0),"") -> 0.38083333 | G32: =IF(C32<>"",(F32+2)/4*100,"") -> 59.520833 | H32: =IF(C32<>"",D32/G32,"") -> 0 | I32: =IF(C32<>"",H32*E32,"") -> 0 | J32: {=_xlfn.LET( _xlpm.p, $D$31:$D$36, _xlpm.s, $E$31:$E$36, _xlpm.v, $G$31:$G$36, _xlpm.sdec, IF(MAX(_xlpm.s)>1, _xlpm.s/100, _xlpm.s), _xlpm.wsum, SUM(_xlpm.sdec), _xlpm.marketP, IF(_xlpm.wsum=0, NA(), SUMPRODUCT(_xlpm.p, _xlpm.sdec)/_xlpm.wsum), _xlpm.marketV, IF(_xlpm.wsum=0, NA(), SUMPRODUCT(_xlpm.v, _xlpm.sdec)/_xlpm.wsum), _xlpm.floorPct, $B$45, _xlpm.pmax, MAX(_xlpm.p), _xlpm.floorP, _xlpm.floorPct * _xlpm.pmax, _xlpm.slope, IF(_xlpm.marketV=0, NA(), (_xlpm.marketP - _xlpm.floorP) / _xlpm.marketV), _xlpm.floorP + _xlpm.slope * INDEX(_xlpm.v, ROW()-30) )} -> #N/A
B33: 3 | C33: =IF(F13<>"",F13,"") -> Parchment | D33: =_xlfn.XLOOKUP($C33,'Step 2 competition'!$B$18:$B$23,'Step 2 competition'!$C$18:$C$23,"",0) -> 0 | E33: =_xlfn.XLOOKUP($C33,'Step 2 competition'!$B$29:$B$34,'Step 2 competition'!$C$29:$C$34,"",0) -> 0 | F33: =IF(C33<>"",_xlfn.XLOOKUP(C33,$D$13:$I$13,$D$22:$I$22,"",0),"") -> 0.655 | G33: =IF(C33<>"",(F33+2)/4*100,"") -> 66.375 | H33: =IF(C33<>"",D33/G33,"") -> 0 | I33: =IF(C33<>"",H33*E33,"") -> 0 | J33: {=_xlfn.LET( _xlpm.p, $D$31:$D$36, _xlpm.s, $E$31:$E$36, _xlpm.v, $G$31:$G$36, _xlpm.sdec, IF(MAX(_xlpm.s)>1, _xlpm.s/100, _xlpm.s), _xlpm.wsum, SUM(_xlpm.sdec), _xlpm.marketP, IF(_xlpm.wsum=0, NA(), SUMPRODUCT(_xlpm.p, _xlpm.sdec)/_xlpm.wsum), _xlpm.marketV, IF(_xlpm.wsum=0, NA(), SUMPRODUCT(_xlpm.v, _xlpm.sdec)/_xlpm.wsum), _xlpm.floorPct, $B$45, _xlpm.pmax, MAX(_xlpm.p), _xlpm.floorP, _xlpm.floorPct * _xlpm.pmax, _xlpm.slope, IF(_xlpm.marketV=0, NA(), (_xlpm.marketP - _xlpm.floorP) / _xlpm.marketV), _xlpm.floorP + _xlpm.slope * INDEX(_xlpm.v, ROW()-30) )} -> #N/A
B34: 4 | C34: =IF(G13<>"",G13,"") -> Canvas | D34: =_xlfn.XLOOKUP($C34,'Step 2 competition'!$B$18:$B$23,'Step 2 competition'!$C$18:$C$23,"",0) -> 0 | E34: =_xlfn.XLOOKUP($C34,'Step 2 competition'!$B$29:$B$34,'Step 2 competition'!$C$29:$C$34,"",0) -> 0 | F34: =IF(C34<>"",_xlfn.XLOOKUP(C34,$D$13:$I$13,$D$22:$I$22,"",0),"") -> 0.435 | G34: =IF(C34<>"",(F34+2)/4*100,"") -> 60.875 | H34: =IF(C34<>"",D34/G34,"") -> 0 | I34: =IF(C34<>"",H34*E34,"") -> 0 | J34: {=_xlfn.LET( _xlpm.p, $D$31:$D$36, _xlpm.s, $E$31:$E$36, _xlpm.v, $G$31:$G$36, _xlpm.sdec, IF(MAX(_xlpm.s)>1, _xlpm.s/100, _xlpm.s), _xlpm.wsum, SUM(_xlpm.sdec), _xlpm.marketP, IF(_xlpm.wsum=0, NA(), SUMPRODUCT(_xlpm.p, _xlpm.sdec)/_xlpm.wsum), _xlpm.marketV, IF(_xlpm.wsum=0, NA(), SUMPRODUCT(_xlpm.v, _xlpm.sdec)/_xlpm.wsum), _xlpm.floorPct, $B$45, _xlpm.pmax, MAX(_xlpm.p), _xlpm.floorP, _xlpm.floorPct * _xlpm.pmax, _xlpm.slope, IF(_xlpm.marketV=0, NA(), (_xlpm.marketP - _xlpm.floorP) / _xlpm.marketV), _xlpm.floorP + _xlpm.slope * INDEX(_xlpm.v, ROW()-30) )} -> #N/A
B35: 5 | C35: =IF(H13<>"",H13,"") -> Territorium | D35: =_xlfn.XLOOKUP($C35,'Step 2 competition'!$B$18:$B$23,'Step 2 competition'!$C$18:$C$23,"",0) -> 0 | E35: =_xlfn.XLOOKUP($C35,'Step 2 competition'!$B$29:$B$34,'Step 2 competition'!$C$29:$C$34,"",0) -> 0 | F35: =IF(C35<>"",_xlfn.XLOOKUP(C35,$D$13:$I$13,$D$22:$I$22,"",0),"") -> -0.275 | G35: =IF(C35<>"",(F35+2)/4*100,"") -> 43.125 | H35: =IF(C35<>"",D35/G35,"") -> 0 | I35: =IF(C35<>"",H35*E35,"") -> 0 | J35: {=_xlfn.LET( _xlpm.p, $D$31:$D$36, _xlpm.s, $E$31:$E$36, _xlpm.v, $G$31:$G$36, _xlpm.sdec, IF(MAX(_xlpm.s)>1, _xlpm.s/100, _xlpm.s), _xlpm.wsum, SUM(_xlpm.sdec), _xlpm.marketP, IF(_xlpm.wsum=0, NA(), SUMPRODUCT(_xlpm.p, _xlpm.sdec)/_xlpm.wsum), _xlpm.marketV, IF(_xlpm.wsum=0, NA(), SUMPRODUCT(_xlpm.v, _xlpm.sdec)/_xlpm.wsum), _xlpm.floorPct, $B$45, _xlpm.pmax, MAX(_xlpm.p), _xlpm.floorP, _xlpm.floorPct * _xlpm.pmax, _xlpm.slope, IF(_xlpm.marketV=0, NA(), (_xlpm.marketP - _xlpm.floorP) / _xlpm.marketV), _xlpm.floorP + _xlpm.slope * INDEX(_xlpm.v, ROW()-30) )} -> #N/A
B36: 6 | C36: =IF(I13<>"",I13,"") -> Credly | D36: =IF(_xlfn.XLOOKUP($C36,'Step 2 competition'!$B$18:$B$23,'Step 2 competition'!$C$18:$C$23,"",0)=0,"",_xlfn.XLOOKUP($C36,'Step 2 competition'!$B$18:$B$23,'Step 2 competition'!$C$18:$C$23,"",0)) | E36: =IF(_xlfn.XLOOKUP($C36,'Step 2 competition'!$B$29:$B$34,'Step 2 competition'!$C$29:$C$34,"",0)=0,"",_xlfn.XLOOKUP($C36,'Step 2 competition'!$B$29:$B$34,'Step 2 competition'!$C$29:$C$34,"",0)) | F36: =IF(C36<>"",_xlfn.XLOOKUP(C36,$D$13:$I$13,$D$22:$I$22,"",0),"") -> 0.9725 | G36: =IF(C36<>"",(F36+2)/4*100,"") -> 74.3125 | H36: =IF(C36<>"",D36/G36,"") -> #VALUE! | I36: =IF(C36<>"",H36*E36,"") -> #VALUE! | J36: {=_xlfn.LET( _xlpm.p, $D$31:$D$36, _xlpm.s, $E$31:$E$36, _xlpm.v, $G$31:$G$36, _xlpm.sdec, IF(MAX(_xlpm.s)>1, _xlpm.s/100, _xlpm.s), _xlpm.wsum, SUM(_xlpm.sdec), _xlpm.marketP, IF(_xlpm.wsum=0, NA(), SUMPRODUCT(_xlpm.p, _xlpm.sdec)/_xlpm.wsum), _xlpm.marketV, IF(_xlpm.wsum=0, NA(), SUMPRODUCT(_xlpm.v, _xlpm.sdec)/_xlpm.wsum), _xlpm.floorPct, $B$45, _xlpm.pmax, MAX(_xlpm.p), _xlpm.floorP, _xlpm.floorPct * _xlpm.pmax, _xlpm.slope, IF(_xlpm.marketV=0, NA(), (_xlpm.marketP - _xlpm.floorP) / _xlpm.marketV), _xlpm.floorP + _xlpm.slope * INDEX(_xlpm.v, ROW()-30) )} -> #N/A
B38: Market-weighted average price | D38: Market-weighted average value
B39: =SUMPRODUCT(D31:D36,E31:E36)/SUM(E31:E36) -> #DIV/0! | D39: =SUMPRODUCT(E31:E36,G31:G36)/SUM(E31:E36) -> #DIV/0!
F40: Anchor line
B41: Min value | C41: Max value | D41: Value range | F41: Min | G41: Mid | J41: 0 | K41: 7112886.2
B42: =MIN(G32:G36) -> 43.125 | C42: =MAX(G32:G36) -> 74.3125 | D42: =C42-B42 -> 31.1875 | F42: =C45 -> 0 | G42: =B39 -> #DIV/0! | J42: 0 | K42: 15912122
F43: -2 | G43: =SUMPRODUCT(E31:E36,F31:F36)/SUM(E31:E36) -> #DIV/0! | J43: 0
B44: Floor price level | C44: Floor price | D44: Max Price | J44: 0
B45: 0.7 | C45: =MAX(D32:D36)*B45 -> 0 | D45: =MAX(D32:D36) -> 0 | J45: 0
...

Sheet 2024 Revenue
A1: Country | B1: Revenue 2024 | C1: Value driver analysis
A2: Australia | B2: 89588268 | C2: X
A3: China | B3: 27604029 | C3: X
A4: India | B4: 24860878 | C4: X
A5: Nepal | B5: 5970381 | C5: O
A6: Canada | B6: 5626341 | C6: O
A7: Pakistan | B7: 5595099 | C7: O
A8: Philippines | B8: 4048257 | C8: X
A9: United Kingdom | B9: 3765606 | C9: O
A10: New Zealand | B10: 3452158 | C10: O
A11: Sri Lanka | B11: 2873716 | C11: X
A12: United Arab Emirates | B12: 2470242 | C12: X
A13: Turkiye | B13: 2147990 | C13: X
... A21: South Africa | B21: 775664 | C21: X
A22: Malaysia | B22: 641977
A23: Qatar | B23: 629027
A24: Egypt | B24: 479114 | C24: X
A25: Thailand | B25: 400153
A26: Fiji | B26: 362270
A27: Indonesia | B27: 348785
A28: Bhutan | B28: 345442
A29: Taiwan | B29: 338770
A30: Kuwait | B30: 333211
A31: Zimbabwe | B31: 306177
A32: Kenya | B32: 282456
A33: Bahrain | B33: 239523
A34: Nigeria | B34: 227681
A35: Brazil | B35: 203241 | C35: O
A36: Japan | B36: 200161
A37: Ireland | B37: 189945
A38: Oman | B38: 164516
A39: Iraq | B39: 161450
A40: Germany | B40: 145440
A41: Jordan | B41: 120135
A42: France | B42: 113825
A43: Spain | B43: 110879
A44: Norway | B44: 109383
A45: Netherlands | B45: 102402
A46: Papua New Guinea | B46: 98996
A47: Israel | B47: 93974
...
